<?xml version="1.0" ?>
<robot name="robokrub" xmlns:xacro="http://www.ros.org/wiki/xacro">

<xacro:include filename="$(find robokrub_description)/urdf/materials.xacro" />
<xacro:include filename="$(find robokrub_description)/urdf/robokrub.trans" />
<xacro:include filename="$(find robokrub_description)/urdf/robokrub.gazebo" />

<link name="base_footprint"/>

<joint name="base_joint" type="fixed">
  <origin rpy="0 0 0" xyz="0 0 0"/>
  <parent link="base_footprint"/>
  <child link="base_link"/>
</joint>

<link name="base_link">
  <inertial>
    <origin rpy="0 0 0" xyz="-0.009538022388619175 0.0020469906835618636 0.48990829688669746"/>
    <mass value="325.87742909126433"/>
    <inertia ixx="21.63765" ixy="0.027042" ixz="3.508396" iyy="21.668393" iyz="-0.083103" izz="6.527635"/>
  </inertial>
  <visual>
    <origin rpy="0 0 0" xyz="0 0 0"/>
    <geometry>
      <mesh filename="package://robokrub_description/meshes/base_link.stl" scale="0.001 0.001 0.001"/>
    </geometry>
    <material name="acrylic_red"/>
  </visual>
  <collision>
    <origin rpy="0 0 0" xyz="0 0 0"/>
    <geometry>
      <mesh filename="package://robokrub_description/meshes/base_link.stl" scale="0.001 0.001 0.001"/>
    </geometry>
  </collision>
</link>

<link name="realsense_base_1">
  <inertial>
    <origin rpy="0 0 0" xyz="-0.0027131980112905657 0.02508250152882424 0.021830441652814114"/>
    <mass value="0.18079572348329903"/>
    <inertia ixx="0.000645" ixy="-3.3e-05" ixz="-2e-06" iyy="7.5e-05" iyz="-3e-05" izz="0.000659"/>
  </inertial>
  <visual>
    <origin rpy="0 0 0" xyz="0.043071 0.002012 -1.305407"/>
    <geometry>
      <mesh filename="package://robokrub_description/meshes/realsense_base_1.stl" scale="0.001 0.001 0.001"/>
    </geometry>
    <material name="paint_enamel_glossy_yellow"/>
  </visual>
  <collision>
    <origin rpy="0 0 0" xyz="0.043071 0.002012 -1.305407"/>
    <geometry>
      <mesh filename="package://robokrub_description/meshes/realsense_base_1.stl" scale="0.001 0.001 0.001"/>
    </geometry>
  </collision>
</link>

<link name="realsense_mount_1">
  <inertial>
    <origin rpy="0 0 0" xyz="-0.005267302738379002 -0.06014712336963198 -0.0005907286668069833"/>
    <mass value="0.37517379313725696"/>
    <inertia ixx="0.000675" ixy="7e-06" ixz="-0.0" iyy="7.6e-05" iyz="-7e-06" izz="0.000659"/>
  </inertial>
  <visual>
    <origin rpy="0 0 0" xyz="0.028221 -0.005244 -1.334055"/>
    <geometry>
      <mesh filename="package://robokrub_description/meshes/realsense_mount_1.stl" scale="0.001 0.001 0.001"/>
    </geometry>
    <material name="paint_enamel_glossy_red"/>
  </visual>
  <collision>
    <origin rpy="0 0 0" xyz="0.028221 -0.005244 -1.334055"/>
    <geometry>
      <mesh filename="package://robokrub_description/meshes/realsense_mount_1.stl" scale="0.001 0.001 0.001"/>
    </geometry>
  </collision>
</link>

<link name="left_back_wheel_1">
  <inertial>
    <origin rpy="0 0 0" xyz="-6.985816848464887e-07 0.03990565025821191 -0.00020828945902967577"/>
    <mass value="0.5279092736345865"/>
    <inertia ixx="0.002877" ixy="-0.0" ixz="0.0" iyy="0.005024" iyz="-2e-06" izz="0.002872"/>
  </inertial>
  <visual>
    <origin rpy="0 0 0" xyz="0.091537 -0.23228 -0.125754"/>
    <geometry>
      <mesh filename="package://robokrub_description/meshes/left_back_wheel_1.stl" scale="0.001 0.001 0.001"/>
    </geometry>
    <material name="nylon_66_white"/>
  </visual>
  <collision>
    <origin rpy="0 0 0" xyz="0.091537 -0.23228 -0.125754"/>
    <geometry>
      <mesh filename="package://robokrub_description/meshes/left_back_wheel_1.stl" scale="0.001 0.001 0.001"/>
    </geometry>
  </collision>
</link>

<link name="right_back_wheel_1">
  <inertial>
    <origin rpy="0 0 0" xyz="7.401248483945855e-07 -0.04009479747167047 -0.00020992648040177309"/>
    <mass value="0.5279102095874385"/>
    <inertia ixx="0.002877" ixy="0.0" ixz="0.0" iyy="0.005024" iyz="-2e-06" izz="0.002872"/>
  </inertial>
  <visual>
    <origin rpy="0 0 0" xyz="0.091537 0.237108 -0.125754"/>
    <geometry>
      <mesh filename="package://robokrub_description/meshes/right_back_wheel_1.stl" scale="0.001 0.001 0.001"/>
    </geometry>
    <material name="nylon_66_white"/>
  </visual>
  <collision>
    <origin rpy="0 0 0" xyz="0.091537 0.237108 -0.125754"/>
    <geometry>
      <mesh filename="package://robokrub_description/meshes/right_back_wheel_1.stl" scale="0.001 0.001 0.001"/>
    </geometry>
  </collision>
</link>

<link name="right_front_wheel_1">
  <inertial>
    <origin rpy="0 0 0" xyz="-8.441077709031575e-08 0.02000002832060535 -5.260305331600268e-08"/>
    <mass value="0.2736860294560353"/>
    <inertia ixx="0.000513" ixy="0.0" ixz="-0.0" iyy="0.000989" iyz="0.0" izz="0.000513"/>
  </inertial>
  <visual>
    <origin rpy="0 0 0" xyz="-0.361852 0.255643 -0.073625"/>
    <geometry>
      <mesh filename="package://robokrub_description/meshes/right_front_wheel_1.stl" scale="0.001 0.001 0.001"/>
    </geometry>
    <material name="rubber_soft"/>
  </visual>
  <collision>
    <origin rpy="0 0 0" xyz="-0.361852 0.255643 -0.073625"/>
    <geometry>
      <mesh filename="package://robokrub_description/meshes/right_front_wheel_1.stl" scale="0.001 0.001 0.001"/>
    </geometry>
  </collision>
</link>

<link name="left_front_wheel_1">
  <inertial>
    <origin rpy="0 0 0" xyz="-3.7668105412613784e-08 -0.020000008606704395 9.616323444483488e-08"/>
    <mass value="0.27368611154659667"/>
    <inertia ixx="0.000513" ixy="-0.0" ixz="0.0" iyy="0.000989" iyz="0.0" izz="0.000513"/>
  </inertial>
  <visual>
    <origin rpy="0 0 0" xyz="-0.361852 -0.250815 -0.073625"/>
    <geometry>
      <mesh filename="package://robokrub_description/meshes/left_front_wheel_1.stl" scale="0.001 0.001 0.001"/>
    </geometry>
    <material name="rubber_soft"/>
  </visual>
  <collision>
    <origin rpy="0 0 0" xyz="-0.361852 -0.250815 -0.073625"/>
    <geometry>
      <mesh filename="package://robokrub_description/meshes/left_front_wheel_1.stl" scale="0.001 0.001 0.001"/>
    </geometry>
  </collision>
</link>

<link name="Hokuyo_UST-10LX__2__v1_1">
  <inertial>
    <origin rpy="0 0 0" xyz="-0.000648703140906981 4.199830898107566e-06 0.02971249528884501"/>
    <mass value="0.36783477848639723"/>
    <inertia ixx="0.0002" ixy="0.0" ixz="1e-06" iyy="0.000206" iyz="0.0" izz="0.000127"/>
  </inertial>
  <visual>
    <origin rpy="0 0 0" xyz="-0.349863 0.002451 -0.231288"/>
    <geometry>
      <mesh filename="package://robokrub_description/meshes/Hokuyo_UST-10LX__2__v1_1.stl" scale="0.001 0.001 0.001"/>
    </geometry>
    <material name="opaque2551648"/>
  </visual>
  <collision>
    <origin rpy="0 0 0" xyz="-0.349863 0.002451 -0.231288"/>
    <geometry>
      <mesh filename="package://robokrub_description/meshes/Hokuyo_UST-10LX__2__v1_1.stl" scale="0.001 0.001 0.001"/>
    </geometry>
  </collision>
</link>

<joint name="realsense_yaw_joint" type="continuous">
  <origin rpy="0 0 0" xyz="-0.043071 -0.002012 1.305407"/>
  <parent link="base_link"/>
  <child link="realsense_base_1"/>
  <axis xyz="-0.000175 0.002437 -0.999997"/>
</joint>

<joint name="realsense_pitch_joint" type="continuous">
  <origin rpy="0 0 0" xyz="0.01485 -0.003232 0.028648"/>
  <parent link="realsense_base_1"/>
  <child link="realsense_mount_1"/>
  <axis xyz="-0.004129 -0.999989 0.002438"/>
</joint>

<joint name="left_back_wheel_joint" type="continuous">
  <origin rpy="0 0 0" xyz="-0.091537 0.23228 0.125754"/>
  <parent link="base_link"/>
  <child link="left_back_wheel_1"/>
  <axis xyz="0.0 1.0 -0.0"/>
</joint>

<joint name="right_back_wheel_joint" type="continuous">
  <origin rpy="0 0 0" xyz="-0.091537 -0.237108 0.125754"/>
  <parent link="base_link"/>
  <child link="right_back_wheel_1"/>
  <axis xyz="-0.0 1.0 0.0"/>
</joint>

<joint name="right_front_wheel_joint" type="fixed">
  <origin rpy="0 0 0" xyz="0.361852 -0.255643 0.073625"/>
  <parent link="base_link"/>
  <child link="right_front_wheel_1"/>
</joint>

<joint name="left_front_wheel_joint" type="fixed">
  <origin rpy="0 0 0" xyz="0.361852 0.250815 0.073625"/>
  <parent link="base_link"/>
  <child link="left_front_wheel_1"/>
</joint>

<joint name="lidar_joint" type="fixed">
  <origin rpy="0 0 0" xyz="0.349863 -0.002451 0.231288"/>
  <parent link="base_link"/>
  <child link="Hokuyo_UST-10LX__2__v1_1"/>
</joint>

</robot>
