<?xml version="1.0" ?>
<robot name="robokrub" xmlns:xacro="http://www.ros.org/wiki/xacro">

<xacro:include filename="$(find robokrub_description)/urdf/materials.xacro" />
<xacro:include filename="$(find robokrub_description)/urdf/robokrub.trans" />
<xacro:include filename="$(find robokrub_description)/urdf/robokrub.gazebo" />

<link name="base_footprint"/>

<joint name="base_joint" type="fixed">
  <parent link="base_footprint"/>
  <child link="base_link"/>
  <origin xyz="0.0 0.0 0.0" rpy="0 0 0"/>
</joint>

<link name="base_link">
  <inertial>
    <origin rpy="0 0 0" xyz="0.368417977611381 0.004268990683561617 0.4899082968866969"/>
    <mass value="325.87742909126433"/>
    <inertia ixx="21.63765" ixy="0.027042" ixz="3.508396" iyy="21.668393" iyz="-0.083103" izz="6.527635"/>
  </inertial>
  <visual>
    <origin rpy="0 0 0" xyz="0 0 0"/>
    <geometry>
      <mesh filename="package://robokrub_description/meshes/base_link.stl" scale="0.001 0.001 0.001"/>
    </geometry>
    <material name="acrylic_red"/>
  </visual>
  <collision>
    <origin rpy="0 0 0" xyz="0 0 0"/>
    <geometry>
      <mesh filename="package://robokrub_description/meshes/base_link.stl" scale="0.001 0.001 0.001"/>
    </geometry>
  </collision>
</link>

<link name="realsense_base_1">
  <inertial>
    <origin rpy="0 0 0" xyz="-0.0027131980112899967 0.025082501528824137 0.021830441652816335"/>
    <mass value="0.18079572348329903"/>
    <inertia ixx="0.000645" ixy="-3.3e-05" ixz="-2e-06" iyy="7.5e-05" iyz="-3e-05" izz="0.000659"/>
  </inertial>
  <visual>
    <origin rpy="0 0 0" xyz="-0.334885 -0.00021 -1.305407"/>
    <geometry>
      <mesh filename="package://robokrub_description/meshes/realsense_base_1.stl" scale="0.001 0.001 0.001"/>
    </geometry>
    <material name="paint_enamel_glossy_yellow"/>
  </visual>
  <collision>
    <origin rpy="0 0 0" xyz="-0.334885 -0.00021 -1.305407"/>
    <geometry>
      <mesh filename="package://robokrub_description/meshes/realsense_base_1.stl" scale="0.001 0.001 0.001"/>
    </geometry>
  </collision>
</link>

<link name="realsense_mount_1">
  <inertial>
    <origin rpy="0 0 0" xyz="-0.005267302738378554 -0.06014712336963212 -0.0005907286668045408"/>
    <mass value="0.37517379313725696"/>
    <inertia ixx="0.000675" ixy="7e-06" ixz="-0.0" iyy="7.6e-05" iyz="-7e-06" izz="0.000659"/>
  </inertial>
  <visual>
    <origin rpy="0 0 0" xyz="-0.349735 -0.061978 -1.334055"/>
    <geometry>
      <mesh filename="package://robokrub_description/meshes/realsense_mount_1.stl" scale="0.001 0.001 0.001"/>
    </geometry>
    <material name="paint_enamel_glossy_red"/>
  </visual>
  <collision>
    <origin rpy="0 0 0" xyz="-0.349735 -0.061978 -1.334055"/>
    <geometry>
      <mesh filename="package://robokrub_description/meshes/realsense_mount_1.stl" scale="0.001 0.001 0.001"/>
    </geometry>
  </collision>
</link>

<link name="left_back_wheel_1">
  <inertial>
    <origin rpy="0 0 0" xyz="-6.985816842774994e-07 0.03990565025821208 -0.00020828945903036966"/>
    <mass value="0.5279092736345865"/>
    <inertia ixx="0.002877" ixy="-0.0" ixz="0.0" iyy="0.005024" iyz="-2e-06" izz="0.002872"/>
  </inertial>
  <visual>
    <origin rpy="0 0 0" xyz="-0.286419 -0.234502 -0.125754"/>
    <geometry>
      <mesh filename="package://robokrub_description/meshes/left_back_wheel_1.stl" scale="0.001 0.001 0.001"/>
    </geometry>
    <material name="nylon_66_white"/>
  </visual>
  <collision>
    <origin rpy="0 0 0" xyz="-0.286419 -0.234502 -0.125754"/>
    <geometry>
      <mesh filename="package://robokrub_description/meshes/left_back_wheel_1.stl" scale="0.001 0.001 0.001"/>
    </geometry>
  </collision>
</link>

<link name="right_back_wheel_1">
  <inertial>
    <origin rpy="0 0 0" xyz="7.401248491301082e-07 -0.04009479747167091 -0.00020992648040230044"/>
    <mass value="0.5279102095874385"/>
    <inertia ixx="0.002877" ixy="0.0" ixz="0.0" iyy="0.005024" iyz="-2e-06" izz="0.002872"/>
  </inertial>
  <visual>
    <origin rpy="0 0 0" xyz="-0.286419 0.234886 -0.125754"/>
    <geometry>
      <mesh filename="package://robokrub_description/meshes/right_back_wheel_1.stl" scale="0.001 0.001 0.001"/>
    </geometry>
    <material name="nylon_66_white"/>
  </visual>
  <collision>
    <origin rpy="0 0 0" xyz="-0.286419 0.234886 -0.125754"/>
    <geometry>
      <mesh filename="package://robokrub_description/meshes/right_back_wheel_1.stl" scale="0.001 0.001 0.001"/>
    </geometry>
  </collision>
</link>

<link name="right_front_wheel_1">
  <inertial>
    <origin rpy="0 0 0" xyz="-8.441077681275999e-08 0.020000028320604546 -5.260305406540322e-08"/>
    <mass value="0.2736860294560353"/>
    <inertia ixx="0.000513" ixy="0.0" ixz="-0.0" iyy="0.000989" iyz="0.0" izz="0.000513"/>
  </inertial>
  <visual>
    <origin rpy="0 0 0" xyz="-0.739808 0.253421 -0.073625"/>
    <geometry>
      <mesh filename="package://robokrub_description/meshes/right_front_wheel_1.stl" scale="0.001 0.001 0.001"/>
    </geometry>
    <material name="rubber_soft"/>
  </visual>
  <collision>
    <origin rpy="0 0 0" xyz="-0.739808 0.253421 -0.073625"/>
    <geometry>
      <mesh filename="package://robokrub_description/meshes/right_front_wheel_1.stl" scale="0.001 0.001 0.001"/>
    </geometry>
  </collision>
</link>

<link name="left_front_wheel_1">
  <inertial>
    <origin rpy="0 0 0" xyz="-3.7668104968524574e-08 -0.020000008606704534 9.616323363992318e-08"/>
    <mass value="0.27368611154659667"/>
    <inertia ixx="0.000513" ixy="-0.0" ixz="0.0" iyy="0.000989" iyz="0.0" izz="0.000513"/>
  </inertial>
  <visual>
    <origin rpy="0 0 0" xyz="-0.739808 -0.253037 -0.073625"/>
    <geometry>
      <mesh filename="package://robokrub_description/meshes/left_front_wheel_1.stl" scale="0.001 0.001 0.001"/>
    </geometry>
    <material name="rubber_soft"/>
  </visual>
  <collision>
    <origin rpy="0 0 0" xyz="-0.739808 -0.253037 -0.073625"/>
    <geometry>
      <mesh filename="package://robokrub_description/meshes/left_front_wheel_1.stl" scale="0.001 0.001 0.001"/>
    </geometry>
  </collision>
</link>

<link name="Hokuyo_UST-10LX__2__v1_1">
  <inertial>
    <origin rpy="0 0 0" xyz="-0.0006487031409065924 4.1998308977922525e-06 0.029712495288844565"/>
    <mass value="0.36783477848639723"/>
    <inertia ixx="0.0002" ixy="0.0" ixz="1e-06" iyy="0.000206" iyz="0.0" izz="0.000127"/>
  </inertial>
  <visual>
    <origin rpy="0 0 0" xyz="-0.727819 0.000229 -0.231288"/>
    <geometry>
      <mesh filename="package://robokrub_description/meshes/Hokuyo_UST-10LX__2__v1_1.stl" scale="0.001 0.001 0.001"/>
    </geometry>
    <material name="opaque2551648"/>
  </visual>
  <collision>
    <origin rpy="0 0 0" xyz="-0.727819 0.000229 -0.231288"/>
    <geometry>
      <mesh filename="package://robokrub_description/meshes/Hokuyo_UST-10LX__2__v1_1.stl" scale="0.001 0.001 0.001"/>
    </geometry>
  </collision>
</link>

<joint name="realsense_pitch_joint" type="continuous">
  <origin rpy="0 0 0" xyz="0.334885 0.00021 1.305407"/>
  <parent link="base_link"/>
  <child link="realsense_base_1"/>
  <axis xyz="-0.000175 0.002437 -0.999997"/>
</joint>

<joint name="realsense_roll_joint" type="continuous">
  <origin rpy="0 0 0" xyz="0.01485 0.061768 0.028648"/>
  <parent link="realsense_base_1"/>
  <child link="realsense_mount_1"/>
  <axis xyz="-0.004129 0.999989 0.002438"/>
</joint>

<joint name="left_back_wheel_joint" type="continuous">
  <origin rpy="0 0 0" xyz="0.286419 0.234502 0.125754"/>
  <parent link="base_link"/>
  <child link="left_back_wheel_1"/>
  <axis xyz="0.0 1.0 -0.0"/>
</joint>

<joint name="right_back_wheel_joint" type="continuous">
  <origin rpy="0 0 0" xyz="0.286419 -0.234886 0.125754"/>
  <parent link="base_link"/>
  <child link="right_back_wheel_1"/>
  <axis xyz="-0.0 1.0 0.0"/>
</joint>

<joint name="right_front_wheel_joint" type="fixed">
  <origin rpy="0 0 0" xyz="0.739808 -0.253421 0.073625"/>
  <parent link="base_link"/>
  <child link="right_front_wheel_1"/>
</joint>

<joint name="left_front_wheel_joint" type="fixed">
  <origin rpy="0 0 0" xyz="0.739808 0.253037 0.073625"/>
  <parent link="base_link"/>
  <child link="left_front_wheel_1"/>
</joint>

<joint name="lidar_joint" type="fixed">
  <origin rpy="0 0 0" xyz="0.727819 -0.000229 0.231288"/>
  <parent link="base_link"/>
  <child link="Hokuyo_UST-10LX__2__v1_1"/>
</joint>

</robot>
